Workbook

Sheet หน้าปก-สรุป
B2: TOTAL IT SERVICES
B3: เอกสารทดสอบการยอมรับของผู้ใช้ (User Acceptance Testing — UAT)
B4: ระบบ IT&MAINT — Smart Asset · Smart Work (ออกแบบใหม่จาก SmartEAM 360 v2.0.0) · UX/UI Mockup
B6: ชื่อโครงการ | C6: TOTAL IT SERVICES — ระบบบริหารทรัพย์สินและงานซ่อมบำรุง IT & Maintenance
B7: เวอร์ชันเอกสาร | C7: 1.0 (ฉบับร่างสำหรับ UAT รอบที่ 1)
B8: วันที่จัดทำ | C8: 17/10/2569
B9: ระบบอ้างอิง | C9: SmartEAM 360 v2.0.0 (ระบบเดิม) + หน้าจอ Mockup ใหม่ 27 ไฟล์ (24 หน้าจอไม่ซ้ำ) (ธีมมืด navy, ภาษาไทย, ปี พ.ศ.)
B10: ขอบเขตการทดสอบ | C10: ทุกเมนูของระบบ: ภาพรวม (Command Center, จอ TV, ปฏิทินรวม) · ทรัพย์สิน (ทะเบียนกลาง, พิมพ์ป้าย QR/Barcode, สินทรัพย์ถาวร & ค่าเสื่อม, โอนย้าย/ยืม-คืน/จำหน่าย, IT Asset & License, EAM, ติดตามตำแหน่ง, ตรวจนับ, DAM) · ซ่อมบำรุง (WO, ใบแจ้งซ่อม, PM, Predictive/IoT, สอบเทียบ) · คลัง & จัดซื้อ (อะไหล่, PR/PO & สัญญา, ต้นทุน & งบประมาณ) · วิเคราะห์ (RCA/FMEA/CAPA, รายงาน & KPI) · ระบบ (ผู้ใช้, RBAC, ข้อมูลหลัก & Custom Field, ตั้งค่า, การแจ้งเตือน & Cron, REST API & Token, Audit Log) รวมถึง End-to-End ข้ามโมดูล, Multi-site, วันที่ พ.ศ., RBAC และ UI/Responsive
B11: นอกขอบเขต | C11: Performance/Load test เต็มรูปแบบ, Penetration test, การย้ายข้อมูลจริง (Data migration) — ทดสอบแยกตามแผนอื่น
B12: หมายเหตุหน้าจอ | C12: เมนูที่ยังไม่มี mockup (พิมพ์ป้าย QR/Barcode, REST API & Token, Audit Log) เขียน Test Case จากข้อกำหนดระบบเดิม และระบุ "ยังไม่มีหน้าจอ mockup" ในคอลัมน์หมายเหตุ
B13: สภาพแวดล้อมทดสอบ | C13: URL UAT: ______________________ ฐานข้อมูลทดสอบ: ______________________ รอบ Build/เวอร์ชัน: __________
B14: อุปกรณ์/เบราว์เซอร์ | C14: Desktop 1920×1080 และ 1366×768 (Chrome, Edge, Safari ล่าสุด) · Mobile 375×667 (iPhone SE/Android) · จอ TV 1920×1080 · เครื่องอ่าน Barcode/RFID และมือถือสำหรับสแกน QR (ถ้ามี)
B15: ข้อมูลทดสอบ | C15: ไซต์: โรงงานสมุทรสาคร (SKN), โรงงานระยอง (RYG) · ทรัพย์สินตัวอย่าง: CONV-03, MTR-007, CMP-02, CNC-001, SRV-001, NB-0231, GAU-011, VH-001 · คลัง: WH-SKN, WH-RYG · ปีงบประมาณ 2569
B17: สรุปผลการทดสอบรายโมดูล (อัปเดตอัตโนมัติจากชีต Test Cases)
B18: โมดูล | C18: รหัส (Prefix) | D18: หน้าจอ Mockup อ้างอิง | E18: จำนวน TC | F18: ผ่าน | G18: ไม่ผ่าน | H18: ติดเงื่อนไข | I18: ยังไม่ทดสอบ | J18: % ผ่าน | K18: % ดำเนินการ | L18: High (TC)
B19: ส่วนกลาง (Shell / Navigation / ทั่วไป) | C19: GEN | D19: ทุกหน้าจอ (c916d36c เป็นหลัก) | E19: =COUNTIF('Test Cases'!$B$2:$B$546,B19) | F19: =COUNTIFS('Test Cases'!$B$2:$B$546,$B19,'Test Cases'!$M$2:$M$546,"ผ่าน") | G19: =COUNTIFS('Test Cases'!$B$2:$B$546,$B19,'Test Cases'!$M$2:$M$546,"ไม่ผ่าน") | H19: =COUNTIFS('Test Cases'!$B$2:$B$546,$B19,'Test Cases'!$M$2:$M$546,"ติดเงื่อนไข") | I19: =COUNTIFS('Test Cases'!$B$2:$B$546,$B19,'Test Cases'!$M$2:$M$546,"ยังไม่ทดสอบ") | J19: =IFERROR(F19/(F19+G19+H19),0) | K19: =IFERROR((F19+G19+H19)/E19,0) | L19: =COUNTIFS('Test Cases'!$B$2:$B$546,$B19,'Test Cases'!$J$2:$J$546,"High")
B20: Command Center (แดชบอร์ด) | C20: DSH | D20: c916d36c | E20: =COUNTIF('Test Cases'!$B$2:$B$546,B20) | F20: =COUNTIFS('Test Cases'!$B$2:$B$546,$B20,'Test Cases'!$M$2:$M$546,"ผ่าน") | G20: =COUNTIFS('Test Cases'!$B$2:$B$546,$B20,'Test Cases'!$M$2:$M$546,"ไม่ผ่าน") | H20: =COUNTIFS('Test Cases'!$B$2:$B$546,$B20,'Test Cases'!$M$2:$M$546,"ติดเงื่อนไข") | I20: =COUNTIFS('Test Cases'!$B$2:$B$546,$B20,'Test Cases'!$M$2:$M$546,"ยังไม่ทดสอบ") | J20: =IFERROR(F20/(F20+G20+H20),0) | K20: =IFERROR((F20+G20+H20)/E20,0) | L20: =COUNTIFS('Test Cases'!$B$2:$B$546,$B20,'Test Cases'!$J$2:$J$546,"High")
B21: จอแสดงผล TV | C21: TV | D21: 2f8beddb | E21: =COUNTIF('Test Cases'!$B$2:$B$546,B21) | F21: =COUNTIFS('Test Cases'!$B$2:$B$546,$B21,'Test Cases'!$M$2:$M$546,"ผ่าน") | G21: =COUNTIFS('Test Cases'!$B$2:$B$546,$B21,'Test Cases'!$M$2:$M$546,"ไม่ผ่าน") | H21: =COUNTIFS('Test Cases'!$B$2:$B$546,$B21,'Test Cases'!$M$2:$M$546,"ติดเงื่อนไข") | I21: =COUNTIFS('Test Cases'!$B$2:$B$546,$B21,'Test Cases'!$M$2:$M$546,"ยังไม่ทดสอบ") | J21: =IFERROR(F21/(F21+G21+H21),0) | K21: =IFERROR((F21+G21+H21)/E21,0) | L21: =COUNTIFS('Test Cases'!$B$2:$B$546,$B21,'Test Cases'!$J$2:$J$546,"High")
B22: ปฏิทินรวม (Master Calendar) | C22: CAL | D22: f7099461 | E22: =COUNTIF('Test Cases'!$B$2:$B$546,B22) | F22: =COUNTIFS('Test Cases'!$B$2:$B$546,$B22,'Test Cases'!$M$2:$M$546,"ผ่าน") | G22: =COUNTIFS('Test Cases'!$B$2:$B$546,$B22,'Test Cases'!$M$2:$M$546,"ไม่ผ่าน") | H22: =COUNTIFS('Test Cases'!$B$2:$B$546,$B22,'Test Cases'!$M$2:$M$546,"ติดเงื่อนไข") | I22: =COUNTIFS('Test Cases'!$B$2:$B$546,$B22,'Test Cases'!$M$2:$M$546,"ยังไม่ทดสอบ") | J22: =IFERROR(F22/(F22+G22+H22),0) | K22: =IFERROR((F22+G22+H22)/E22,0) | L22: =COUNTIFS('Test Cases'!$B$2:$B$546,$B22,'Test Cases'!$J$2:$J$546,"High")
B23: ทะเบียนทรัพย์สินกลาง | C23: AST | D23: 6bf7b7fb | E23: =COUNTIF('Test Cases'!$B$2:$B$546,B23) | F23: =COUNTIFS('Test Cases'!$B$2:$B$546,$B23,'Test Cases'!$M$2:$M$546,"ผ่าน") | G23: =COUNTIFS('Test Cases'!$B$2:$B$546,$B23,'Test Cases'!$M$2:$M$546,"ไม่ผ่าน") | H23: =COUNTIFS('Test Cases'!$B$2:$B$546,$B23,'Test Cases'!$M$2:$M$546,"ติดเงื่อนไข") | I23: =COUNTIFS('Test Cases'!$B$2:$B$546,$B23,'Test Cases'!$M$2:$M$546,"ยังไม่ทดสอบ") | J23: =IFERROR(F23/(F23+G23+H23),0) | K23: =IFERROR((F23+G23+H23)/E23,0) | L23: =COUNTIFS('Test Cases'!$B$2:$B$546,$B23,'Test Cases'!$J$2:$J$546,"High")
B24: พิมพ์ป้าย QR / Barcode | C24: LBL | D24: — (ไม่มี mockup) | E24: =COUNTIF('Test Cases'!$B$2:$B$546,B24) | F24: =COUNTIFS('Test Cases'!$B$2:$B$546,$B24,'Test Cases'!$M$2:$M$546,"ผ่าน") | G24: =COUNTIFS('Test Cases'!$B$2:$B$546,$B24,'Test Cases'!$M$2:$M$546,"ไม่ผ่าน") | H24: =COUNTIFS('Test Cases'!$B$2:$B$546,$B24,'Test Cases'!$M$2:$M$546,"ติดเงื่อนไข") | I24: =COUNTIFS('Test Cases'!$B$2:$B$546,$B24,'Test Cases'!$M$2:$M$546,"ยังไม่ทดสอบ") | J24: =IFERROR(F24/(F24+G24+H24),0) | K24: =IFERROR((F24+G24+H24)/E24,0) | L24: =COUNTIFS('Test Cases'!$B$2:$B$546,$B24,'Test Cases'!$J$2:$J$546,"High")
B25: สินทรัพย์ถาวร & ค่าเสื่อมราคา | C25: FA | D25: cb49172a | E25: =COUNTIF('Test Cases'!$B$2:$B$546,B25) | F25: =COUNTIFS('Test Cases'!$B$2:$B$546,$B25,'Test Cases'!$M$2:$M$546,"ผ่าน") | G25: =COUNTIFS('Test Cases'!$B$2:$B$546,$B25,'Test Cases'!$M$2:$M$546,"ไม่ผ่าน") | H25: =COUNTIFS('Test Cases'!$B$2:$B$546,$B25,'Test Cases'!$M$2:$M$546,"ติดเงื่อนไข") | I25: =COUNTIFS('Test Cases'!$B$2:$B$546,$B25,'Test Cases'!$M$2:$M$546,"ยังไม่ทดสอบ") | J25: =IFERROR(F25/(F25+G25+H25),0) | K25: =IFERROR((F25+G25+H25)/E25,0) | L25: =COUNTIFS('Test Cases'!$B$2:$B$546,$B25,'Test Cases'!$J$2:$J$546,"High")
B26: โอนย้าย / ยืม-คืน / จำหน่าย | C26: MOV | D26: 58ee5614 | E26: =COUNTIF('Test Cases'!$B$2:$B$546,B26) | F26: =COUNTIFS('Test Cases'!$B$2:$B$546,$B26,'Test Cases'!$M$2:$M$546,"ผ่าน") | G26: =COUNTIFS('Test Cases'!$B$2:$B$546,$B26,'Test Cases'!$M$2:$M$546,"ไม่ผ่าน") | H26: =COUNTIFS('Test Cases'!$B$2:$B$546,$B26,'Test Cases'!$M$2:$M$546,"ติดเงื่อนไข") | I26: =COUNTIFS('Test Cases'!$B$2:$B$546,$B26,'Test Cases'!$M$2:$M$546,"ยังไม่ทดสอบ") | J26: =IFERROR(F26/(F26+G26+H26),0) | K26: =IFERROR((F26+G26+H26)/E26,0) | L26: =COUNTIFS('Test Cases'!$B$2:$B$546,$B26,'Test Cases'!$J$2:$J$546,"High")
B27: IT Asset & License | C27: ITAM | D27: af9d691f + a6aa52ba | E27: =COUNTIF('Test Cases'!$B$2:$B$546,B27) | F27: =COUNTIFS('Test Cases'!$B$2:$B$546,$B27,'Test Cases'!$M$2:$M$546,"ผ่าน") | G27: =COUNTIFS('Test Cases'!$B$2:$B$546,$B27,'Test Cases'!$M$2:$M$546,"ไม่ผ่าน") | H27: =COUNTIFS('Test Cases'!$B$2:$B$546,$B27,'Test Cases'!$M$2:$M$546,"ติดเงื่อนไข") | I27: =COUNTIFS('Test Cases'!$B$2:$B$546,$B27,'Test Cases'!$M$2:$M$546,"ยังไม่ทดสอบ") | J27: =IFERROR(F27/(F27+G27+H27),0) | K27: =IFERROR((F27+G27+H27)/E27,0) | L27: =COUNTIFS('Test Cases'!$B$2:$B$546,$B27,'Test Cases'!$J$2:$J$546,"High")
B28: EAM ลำดับชั้น & Lifecycle | C28: EAM | D28: 88f07cff | E28: =COUNTIF('Test Cases'!$B$2:$B$546,B28) | F28: =COUNTIFS('Test Cases'!$B$2:$B$546,$B28,'Test Cases'!$M$2:$M$546,"ผ่าน") | G28: =COUNTIFS('Test Cases'!$B$2:$B$546,$B28,'Test Cases'!$M$2:$M$546,"ไม่ผ่าน") | H28: =COUNTIFS('Test Cases'!$B$2:$B$546,$B28,'Test Cases'!$M$2:$M$546,"ติดเงื่อนไข") | I28: =COUNTIFS('Test Cases'!$B$2:$B$546,$B28,'Test Cases'!$M$2:$M$546,"ยังไม่ทดสอบ") | J28: =IFERROR(F28/(F28+G28+H28),0) | K28: =IFERROR((F28+G28+H28)/E28,0) | L28: =COUNTIFS('Test Cases'!$B$2:$B$546,$B28,'Test Cases'!$J$2:$J$546,"High")
B29: ติดตามตำแหน่ง (QR · RFID · GPS) | C29: TRK | D29: 3de213f2 | E29: =COUNTIF('Test Cases'!$B$2:$B$546,B29) | F29: =COUNTIFS('Test Cases'!$B$2:$B$546,$B29,'Test Cases'!$M$2:$M$546,"ผ่าน") | G29: =COUNTIFS('Test Cases'!$B$2:$B$546,$B29,'Test Cases'!$M$2:$M$546,"ไม่ผ่าน") | H29: =COUNTIFS('Test Cases'!$B$2:$B$546,$B29,'Test Cases'!$M$2:$M$546,"ติดเงื่อนไข") | I29: =COUNTIFS('Test Cases'!$B$2:$B$546,$B29,'Test Cases'!$M$2:$M$546,"ยังไม่ทดสอบ") | J29: =IFERROR(F29/(F29+G29+H29),0) | K29: =IFERROR((F29+G29+H29)/E29,0) | L29: =COUNTIFS('Test Cases'!$B$2:$B$546,$B29,'Test Cases'!$J$2:$J$546,"High")
B30: ตรวจนับทรัพย์สิน (Stocktake) | C30: STK | D30: 41ca3fb4 | E30: =COUNTIF('Test Cases'!$B$2:$B$546,B30) | F30: =COUNTIFS('Test Cases'!$B$2:$B$546,$B30,'Test Cases'!$M$2:$M$546,"ผ่าน") | G30: =COUNTIFS('Test Cases'!$B$2:$B$546,$B30,'Test Cases'!$M$2:$M$546,"ไม่ผ่าน") | H30: =COUNTIFS('Test Cases'!$B$2:$B$546,$B30,'Test Cases'!$M$2:$M$546,"ติดเงื่อนไข") | I30: =COUNTIFS('Test Cases'!$B$2:$B$546,$B30,'Test Cases'!$M$2:$M$546,"ยังไม่ทดสอบ") | J30: =IFERROR(F30/(F30+G30+H30),0) | K30: =IFERROR((F30+G30+H30)/E30,0) | L30: =COUNTIFS('Test Cases'!$B$2:$B$546,$B30,'Test Cases'!$J$2:$J$546,"High")
... B47: End-to-End (ข้ามโมดูล) | C47: E2E | D47: หลายหน้าจอ — ดูชีต End-to-End Scenarios | E47: =COUNTIF('Test Cases'!$B$2:$B$546,B47) | F47: =COUNTIFS('Test Cases'!$B$2:$B$546,$B47,'Test Cases'!$M$2:$M$546,"ผ่าน") | G47: =COUNTIFS('Test Cases'!$B$2:$B$546,$B47,'Test Cases'!$M$2:$M$546,"ไม่ผ่าน") | H47: =COUNTIFS('Test Cases'!$B$2:$B$546,$B47,'Test Cases'!$M$2:$M$546,"ติดเงื่อนไข") | I47: =COUNTIFS('Test Cases'!$B$2:$B$546,$B47,'Test Cases'!$M$2:$M$546,"ยังไม่ทดสอบ") | J47: =IFERROR(F47/(F47+G47+H47),0) | K47: =IFERROR((F47+G47+H47)/E47,0) | L47: =COUNTIFS('Test Cases'!$B$2:$B$546,$B47,'Test Cases'!$J$2:$J$546,"High")
B48: รวมทั้งหมด | E48: =SUM(E19:E47) | F48: =SUM(F19:F47) | G48: =SUM(G19:G47) | H48: =SUM(H19:H47) | I48: =SUM(I19:I47) | J48: =IFERROR(F48/(F48+G48+H48),0) | K48: =IFERROR((F48+G48+H48)/E48,0) | L48: =SUM(L19:L47)
B49: บทบาทผู้ทดสอบ (อ้างอิง RBAC ของระบบ — 11 บทบาท)
B50: บทบาท | C50: Role key | D50: บัญชีทดสอบ | E50: ขอบเขตข้อมูล | G50: หน้าที่หลักใน UAT
B51: ผู้ดูแลระบบสูงสุด | C51: super_admin | D51: admin | E51: ทั้งหมด | G51: ตั้งค่าระบบ, ผู้ใช้/RBAC, ข้อมูลหลัก & Custom Field, ทดสอบภาพรวมทุกโมดูล
B52: ผู้จัดการทรัพย์สิน | C52: asset_manager | D52: asset.mgr | E52: ทั้งหมด | G52: ทะเบียน, ป้าย QR, โอนย้าย/ยืม-คืน/จำหน่าย, ตรวจนับ, ติดตามตำแหน่ง, DAM
B53: บัญชีสินทรัพย์ | C53: accountant | D53: account | E53: ทั้งหมด | G53: ค่าเสื่อม/ปิดงวด/JV, งบประมาณ, อนุมัติจำหน่าย
B54: ผู้ดูแลระบบ IT | C54: it_admin | D54: it.admin | E54: ทั้งหมด | G54: IT Asset & License, IoT, แจ้งเตือน/Cron, REST API & Token
B55: ผู้จัดการซ่อมบำรุง | C55: maint_manager | D55: maint.mgr | E55: ไซต์ของตน | G55: คัดกรองแจ้งซ่อม, มอบหมาย/อนุมัติ WO, PM, สอบเทียบ, RCA/FMEA
B56: ช่างซ่อมบำรุง | C56: technician | D56: somchai, wichai, thanapol, anucha, preecha | E56: ไซต์ของตน | G56: รับงาน/อัปเดต/ปิด WO, เช็คลิสต์, สแกนตรวจนับ/ตำแหน่ง
B57: เจ้าหน้าที่คลัง | C57: storekeeper | D57: store | E57: ไซต์ของตน | G57: รับเข้า/เบิก/โอน/ปรับยอดอะไหล่, รับของจาก PO
B58: เจ้าหน้าที่จัดซื้อ | C58: purchaser | D58: purchase | E58: ทั้งหมด | G58: สร้าง PR/PO, สัญญา MA/บริการ
B59: ผู้ตรวจสอบ | C59: auditor | D59: auditor | E59: ทั้งหมด (อ่านอย่างเดียว) | G59: ตรวจสอบสิทธิ์อ่านอย่างเดียว, Audit Log, รายงาน
...

Sheet Test Cases
A1: TC ID | B1: โมดูล | C1: หน้าจอ | D1: Scenario | E1: ประเภท | F1: เงื่อนไขก่อนทดสอบ | G1: ขั้นตอนการทดสอบ | H1: ข้อมูลทดสอบ | I1: ผลลัพธ์ที่คาดหวัง | J1: ระดับความสำคัญ | K1: บทบาทผู้ทดสอบ | L1: ผลทดสอบจริง | M1: สถานะ | N1: ผู้ทดสอบ | O1: วันที่ทดสอบ | P1: หมายเหตุ/Defect ID | Q1: อ้างอิงหน้าจอ Mockup
A2: UAT-GEN-001 | B2: ส่วนกลาง (Shell / Navigation / ทั่วไป) | C2: Shell ทุกหน้าจอ | D2: เข้าสู่ระบบด้วยบัญชีที่ถูกต้อง | E2: Functional | F2: มีบัญชีผู้ใช้ admin สถานะใช้งาน | G2: 1. เปิด URL ระบบ 2. กรอก Username/Password 3. กดเข้าสู่ระบบ | H2: admin / รหัสผ่านที่ถูกต้อง | I2: เข้าสู่หน้า Command Center; มุมขวาบนแสดง "Admin · ผู้ดูแลระบบสูงสุด" | J2: High | K2: ผู้ดูแลระบบสูงสุด (admin) | M2: ยังไม่ทดสอบ | P2: หน้า Login ยังไม่มี mockup — อ้างอิงระบบเดิม | Q2: ทุกหน้าจอ (c916d36c เป็นหลัก)
A3: UAT-GEN-002 | B3: ส่วนกลาง (Shell / Navigation / ทั่วไป) | C3: Shell ทุกหน้าจอ | D3: เข้าสู่ระบบด้วยรหัสผ่านผิดเกินจำนวนครั้ง | E3: Negative | F3: มีบัญชี somchai | G3: 1. กรอกรหัสผ่านผิดติดต่อกัน 5 ครั้ง 2. ตรวจข้อความแจ้งเตือน 3. ตรวจ Audit Log | H3: somchai / รหัสผิด | I3: แสดงข้อความภาษาไทยว่ารหัสผ่านไม่ถูกต้อง; ครบเกณฑ์บัญชีถูกล็อก (สถานะ "ถูกล็อก"); Audit Log บันทึก action lockout | J3: High | K3: ช่างซ่อมบำรุง (somchai) | M3: ยังไม่ทดสอบ | P3: หน้า Login ยังไม่มี mockup — อ้างอิงระบบเดิม (Audit action: lockout) | Q3: ทุกหน้าจอ (c916d36c เป็นหลัก)
A4: UAT-GEN-003 | B4: ส่วนกลาง (Shell / Navigation / ทั่วไป) | C4: Shell ทุกหน้าจอ | D4: เมนูด้านซ้ายแสดงครบทุกกลุ่มและไฮไลต์หน้าปัจจุบัน | E4: UI | F4: เข้าสู่ระบบแล้ว | G4: 1. ตรวจกลุ่มเมนู ภาพรวม / ทรัพย์สิน / ซ่อมบำรุง / คลัง & จัดซื้อ / วิเคราะห์ / ระบบ 2. คลิกเมนู "ใบสั่งงาน (WO)" 3. ตรวจสถานะ active ของเมนู | H4: - | I4: แสดงเมนูครบตามโครงสร้าง (รวม พิมพ์ป้าย QR/Barcode, REST API & Token, Audit Log); เมนูหน้าปัจจุบันถูกไฮไลต์; badge จำนวน WO 18, PM 6, คลังอะไหล่ 3 แสดงถูกต้อง | J4: Medium | K4: ผู้ดูแลระบบสูงสุด (admin) | M4: ยังไม่ทดสอบ | Q4: ทุกหน้าจอ (c916d36c เป็นหลัก)
A5: UAT-GEN-004 | B5: ส่วนกลาง (Shell / Navigation / ทั่วไป) | C5: Shell ทุกหน้าจอ | D5: ย่อ/ขยายเมนูด้านซ้าย | E5: UI | F5: เข้าสู่ระบบแล้ว | G5: 1. คลิกปุ่มเมนู (☰) 2. คลิกอีกครั้ง | H5: - | I5: เมนูย่อ/ขยายได้; เนื้อหาหลักปรับความกว้างอัตโนมัติ ไม่ซ้อนทับ | J5: Low | K5: ผู้ดูแลระบบสูงสุด (admin) | M5: ยังไม่ทดสอบ | Q5: ทุกหน้าจอ (c916d36c เป็นหลัก)
A6: UAT-GEN-005 | B6: ส่วนกลาง (Shell / Navigation / ทั่วไป) | C6: Shell ทุกหน้าจอ | D6: ตัวเลือกไซต์ (Multi-site) ที่แถบบน | E6: Functional | F6: เข้าสู่ระบบแล้ว | G6: 1. คลิก dropdown ไซต์ที่แถบบน 2. เลือก "โรงงานระยอง" 3. ตรวจ KPI/ตาราง 4. เปลี่ยนกลับเป็น "ทุกไซต์" | H6: ไซต์: ทุกไซต์ / โรงงานสมุทรสาคร / โรงงานระยอง | I6: ตัวเลือกมี 3 รายการ ทุกไซต์ (ค่าเริ่มต้น), โรงงานสมุทรสาคร, โรงงานระยอง; ข้อมูลในหน้ากรองตามไซต์ที่เลือก; ค่าไซต์คงอยู่เมื่อเปลี่ยนหน้า | J6: High | K6: ผู้ดูแลระบบสูงสุด (admin) | M6: ยังไม่ทดสอบ | Q6: ทุกหน้าจอ (c916d36c เป็นหลัก)
A7: UAT-GEN-006 | B7: ส่วนกลาง (Shell / Navigation / ทั่วไป) | C7: Shell ทุกหน้าจอ | D7: ความสอดคล้องของชื่อไซต์ในทุกหน้าจอ | E7: UI | F7: เข้าสู่ระบบแล้ว | G7: 1. เปิดหน้าจอทุกโมดูลทีละหน้า 2. เปิด dropdown ไซต์และบันทึกชื่อไซต์ที่แสดง | H7: - | I7: ทุกหน้าจอใช้รายชื่อไซต์ชุดเดียวกัน (ทุกไซต์/โรงงานสมุทรสาคร/โรงงานระยอง) ตามข้อมูลหลัก | J7: Medium | K7: ผู้ดูแลระบบสูงสุด (admin) | M7: ยังไม่ทดสอบ | P7: ข้อสังเกตจาก mockup: บางหน้าจอใช้ชื่อไซต์ตัวอย่างต่างกัน (เช่น โรงงานบางนา, โรงงาน A/B, สำนักงานใหญ่) — ควรแก้ให้ตรงข้อมูลหลัก | Q7: ทุกหน้าจอ (c916d36c เป็นหลัก)
A8: UAT-GEN-007 | B8: ส่วนกลาง (Shell / Navigation / ทั่วไป) | C8: Shell ทุกหน้าจอ | D8: ค้นหาทั่วระบบด้วย Ctrl+K | E8: Functional | F8: เข้าสู่ระบบแล้ว | G8: 1. กด Ctrl+K (หรือ ⌘K) 2. พิมพ์ Asset Tag 3. เลือกผลลัพธ์ | H8: คำค้น: CONV-03, WO-2569-0003, NB-0231, M365 | I8: Cursor ไปที่ช่องค้นหา "ค้นหา Asset Tag, S/N, WO, ไลเซนส์…"; แสดงผลลัพธ์จากหลายโมดูล; คลิกแล้วไปยังหน้ารายละเอียดที่ถูกต้อง | J8: Medium | K8: ผู้ดูแลระบบสูงสุด (admin) | M8: ยังไม่ทดสอบ | Q8: ทุกหน้าจอ (c916d36c เป็นหลัก)
A9: UAT-GEN-008 | B9: ส่วนกลาง (Shell / Navigation / ทั่วไป) | C9: Shell ทุกหน้าจอ | D9: ปุ่มลัด "+ แจ้งซ่อม" ที่แถบบน | E9: Functional | F9: เข้าสู่ระบบแล้ว | G9: 1. อยู่หน้าใดก็ได้ (เช่น ทะเบียนทรัพย์สิน) 2. คลิกปุ่ม "+ แจ้งซ่อม" สีส้ม | H9: - | I9: เปิดฟอร์มแจ้งซ่อมได้ทันทีจากทุกหน้า โดยไม่สูญเสียข้อมูลหน้าปัจจุบัน | J9: High | K9: ผู้แจ้งซ่อม/ผู้ใช้งานทั่วไป (user) | M9: ยังไม่ทดสอบ | Q9: ทุกหน้าจอ (c916d36c เป็นหลัก)
A10: UAT-GEN-009 | B10: ส่วนกลาง (Shell / Navigation / ทั่วไป) | C10: Shell ทุกหน้าจอ | D10: กระดิ่งแจ้งเตือน | E10: Functional | F10: มีการแจ้งเตือนค้างอยู่ | G10: 1. คลิกไอคอนกระดิ่ง 2. อ่านรายการแจ้งเตือน | H10: - | I10: แสดงจำนวนและรายการแจ้งเตือนภาษาไทย (เช่น WO เกิน SLA, ไลเซนส์ใกล้หมด); เมื่อเปิดอ่านแล้ว badge ลดลง | J10: Medium | K10: ผู้ดูแลระบบสูงสุด (admin) | M10: ยังไม่ทดสอบ | Q10: ทุกหน้าจอ (c916d36c เป็นหลัก)
A11: UAT-GEN-010 | B11: ส่วนกลาง (Shell / Navigation / ทั่วไป) | C11: Shell ทุกหน้าจอ | D11: สลับธีมมืด/สว่าง | E11: UI | F11: เข้าสู่ระบบแล้ว | G11: 1. คลิกปุ่มสลับธีม 2. ตรวจหน้าจอ 3. รีเฟรชหน้า | H11: - | I11: ธีมเปลี่ยนทั้งหน้า; ตัวอักษร/ไอคอน/กราฟอ่านได้ทั้งสองธีม; ธีมที่เลือกถูกจำหลังรีเฟรช | J11: Low | K11: ผู้ดูแลระบบสูงสุด (admin) | M11: ยังไม่ทดสอบ | Q11: ทุกหน้าจอ (c916d36c เป็นหลัก)
A12: UAT-GEN-011 | B12: ส่วนกลาง (Shell / Navigation / ทั่วไป) | C12: Shell ทุกหน้าจอ | D12: Breadcrumb ใต้แถบบน | E12: UI | F12: เข้าสู่ระบบแล้ว | G12: 1. เปิดหน้า ต้นทุน & งบประมาณ 2. ตรวจ breadcrumb 3. คลิก "หน้าแรก" ใน breadcrumb | H12: - | I12: Breadcrumb ตรงกับกลุ่มเมนู (หน้าแรก / คลัง & จัดซื้อ / ต้นทุน & งบประมาณ); คลิกแล้วนำทางถูกต้อง | J12: Low | K12: ผู้ดูแลระบบสูงสุด (admin) | M12: ยังไม่ทดสอบ | P12: ระบบเดิมแสดง breadcrumb งบประมาณใต้ "วิเคราะห์" ไม่ตรงเมนู — ตรวจว่าแก้แล้ว | Q12: ทุกหน้าจอ (c916d36c เป็นหลัก)
A13: UAT-GEN-012 | B13: ส่วนกลาง (Shell / Navigation / ทั่วไป) | C13: Shell ทุกหน้าจอ | D13: รูปแบบวันที่พุทธศักราช (พ.ศ.) | E13: UI | F13: เข้าสู่ระบบแล้ว | G13: 1. เปิดหน้าที่มีวันที่ (WO, ปฏิทิน, ค่าเสื่อม, ตรวจนับ) 2. ตรวจรูปแบบวันที่ในตาราง/ฟอร์ม/date picker | H13: - | I13: วันที่แสดงเป็น พ.ศ. รูปแบบไทย เช่น "1 ต.ค. 2569"; date picker แสดงปี 2569; ข้อมูลที่บันทึก/ส่งออก API ใช้ ค.ศ. ISO | J13: High | K13: ผู้ดูแลระบบสูงสุด (admin) | M13: ยังไม่ทดสอบ | Q13: ทุกหน้าจอ (c916d36c เป็นหลัก)
A14: UAT-GEN-013 | B14: ส่วนกลาง (Shell / Navigation / ทั่วไป) | C14: Shell ทุกหน้าจอ | D14: รูปแบบจำนวนเงินบาท | E14: UI | F14: เข้าสู่ระบบแล้ว | G14: 1. เปิดหน้า ทะเบียนทรัพย์สิน, PR/PO, งบประมาณ 2. ตรวจรูปแบบตัวเลข | H14: - | I14: ตัวเลขเงินมีคั่นหลักพัน ทศนิยม 2 ตำแหน่งในตาราง; KPI ย่อแบบไทย (ลบ., พัน) สอดคล้องกันทุกหน้า | J14: Medium | K14: ผู้ดูแลระบบสูงสุด (admin) | M14: ยังไม่ทดสอบ | Q14: ทุกหน้าจอ (c916d36c เป็นหลัก)
A15: UAT-GEN-014 | B15: ส่วนกลาง (Shell / Navigation / ทั่วไป) | C15: Shell ทุกหน้าจอ | D15: การ์ด "Customize Field — เพิ่มฟิลด์เองได้" ที่ท้ายเมนู | E15: Functional | F15: เข้าสู่ระบบแล้ว | G15: 1. คลิกการ์ด Customize Field ที่ท้าย sidebar | H15: - | I15: นำไปยังหน้า ข้อมูลหลัก > ฟิลด์เพิ่มเติมตามหมวด (Custom Field Builder) | J15: Low | K15: ผู้ดูแลระบบสูงสุด (admin) | M15: ยังไม่ทดสอบ | Q15: ทุกหน้าจอ (c916d36c เป็นหลัก)
A16: UAT-GEN-015 | B16: ส่วนกลาง (Shell / Navigation / ทั่วไป) | C16: Shell ทุกหน้าจอ | D16: Pagination มาตรฐานของหน้ารายการ | E16: UI | F16: หน้ารายการมีข้อมูลมากกว่า 1 หน้า | G16: 1. เปิดหน้ารายการ เช่น Audit Log/ทะเบียนทรัพย์สิน 2. คลิกหน้าถัดไป/ก่อนหน้า | H16: - | I16: แสดงข้อความ "แสดง 1–N จาก N รายการ"; ปุ่มก่อนหน้าปิดใช้งานที่หน้าแรก; เปลี่ยนหน้าได้ถูกต้อง | J16: Low | K16: ผู้ดูแลระบบสูงสุด (admin) | M16: ยังไม่ทดสอบ | Q16: ทุกหน้าจอ (c916d36c เป็นหลัก)
A17: UAT-GEN-016 | B17: ส่วนกลาง (Shell / Navigation / ทั่วไป) | C17: Shell ทุกหน้าจอ | D17: เข้าถึงหน้าที่ไม่มีสิทธิ์ผ่าน URL ตรง | E17: Permission | F17: ล็อกอินเป็น user (ผู้แจ้งซ่อม) | G17: 1. พิมพ์ URL หน้า ตั้งค่าระบบ หรือ บทบาท & สิทธิ์ โดยตรง | H17: - | I17: ระบบปฏิเสธการเข้าถึง (403/ข้อความไม่มีสิทธิ์) และไม่แสดงเมนูที่ไม่มีสิทธิ์ใน sidebar | J17: High | K17: ผู้แจ้งซ่อม/ผู้ใช้งานทั่วไป (user) | M17: ยังไม่ทดสอบ | Q17: ทุกหน้าจอ (c916d36c เป็นหลัก)
A18: UAT-GEN-017 | B18: ส่วนกลาง (Shell / Navigation / ทั่วไป) | C18: Shell ทุกหน้าจอ | D18: ออกจากระบบ | E18: Functional | F18: เข้าสู่ระบบแล้ว | G18: 1. คลิก avatar มุมขวาบน 2. เลือกออกจากระบบ 3. กดปุ่ม Back ของเบราว์เซอร์ | H18: - | I18: กลับไปหน้า Login; กด Back ไม่สามารถเข้าหน้าเดิมได้; Audit Log บันทึก logout | J18: Medium | K18: ผู้ดูแลระบบสูงสุด (admin) | M18: ยังไม่ทดสอบ | Q18: ทุกหน้าจอ (c916d36c เป็นหลัก)
A19: UAT-GEN-018 | B19: ส่วนกลาง (Shell / Navigation / ทั่วไป) | C19: Shell ทุกหน้าจอ | D19: Toast แจ้งผลการทำงาน | E19: UI | F19: เข้าสู่ระบบแล้ว | G19: 1. บันทึกฟอร์มใดก็ได้สำเร็จ 2. สังเกต toast | H19: - | I19: Toast ภาษาไทยแสดงมุมจอ อ่านได้ชัดบนธีมมืด หายไปเองภายในไม่กี่วินาที และไม่บังปุ่มสำคัญ | J19: Low | K19: ผู้ดูแลระบบสูงสุด (admin) | M19: ยังไม่ทดสอบ | Q19: ทุกหน้าจอ (c916d36c เป็นหลัก)
A20: UAT-GEN-019 | B20: ส่วนกลาง (Shell / Navigation / ทั่วไป) | C20: Shell ทุกหน้าจอ | D20: ติดตั้งเป็นแอป (PWA) | E20: Functional | F20: ใช้ Chrome/Edge บนมือถือหรือ Desktop | G20: 1. คลิก "ติดตั้งแอป" ที่ท้ายเมนู 2. เปิดแอปจากไอคอนที่ติดตั้ง | H20: - | I20: ติดตั้งได้และเปิดแบบ standalone; ล็อกอินและเมนูทำงานปกติ | J20: Low | K20: ผู้ดูแลระบบสูงสุด (admin) | M20: ยังไม่ทดสอบ | P20: ฟีเจอร์จากระบบเดิม ยังไม่มีใน mockup | Q20: ทุกหน้าจอ (c916d36c เป็นหลัก)
A21: UAT-GEN-020 | B21: ส่วนกลาง (Shell / Navigation / ทั่วไป) | C21: Shell ทุกหน้าจอ | D21: ค้นหาไม่พบข้อมูล (Shell ทุกหน้าจอ) | E21: Negative | F21: เข้าสู่ระบบแล้ว และอยู่ที่หน้าShell ทุกหน้าจอ | G21: 1. พิมพ์คำค้นที่ไม่มีอยู่จริงในช่อง "ค้นหา Asset Tag, S/N, WO, ไลเซนส์…" 2. สังเกตตาราง/รายการ | H21: คำค้น: ZZZ-NOTFOUND-999 | I21: ตารางแสดงข้อความว่างภาษาไทย (เช่น "ไม่พบ...ตามตัวกรอง") ไม่แสดง error และ pagination/ตัวนับปรับเป็น 0 รายการ | J21: Low | K21: ผู้ดูแลระบบสูงสุด (admin) | M21: ยังไม่ทดสอบ | Q21: ทุกหน้าจอ (c916d36c เป็นหลัก)
A22: UAT-GEN-021 | B22: ส่วนกลาง (Shell / Navigation / ทั่วไป) | C22: Shell ทุกหน้าจอ | D22: ค้นหาด้วยคำค้นที่มีอยู่จริง (Shell ทุกหน้าจอ) | E22: Functional | F22: เข้าสู่ระบบแล้ว และอยู่ที่หน้าShell ทุกหน้าจอ | G22: 1. พิมพ์คำค้นในช่อง "ค้นหา Asset Tag, S/N, WO, ไลเซนส์…" 2. ตรวจรายการที่แสดง 3. ล้างคำค้น | H22: คำค้น: MTR-007 | I22: แสดงเฉพาะรายการที่ตรงกับคำค้น (ผลการค้นหาทรัพย์สิน MTR-007); เมื่อล้างคำค้นรายการกลับมาครบ | J22: Medium | K22: ผู้ดูแลระบบสูงสุด (admin) | M22: ยังไม่ทดสอบ | Q22: ทุกหน้าจอ (c916d36c เป็นหลัก)
A23: UAT-GEN-022 | B23: ส่วนกลาง (Shell / Navigation / ทั่วไป) | C23: Shell ทุกหน้าจอ | D23: แสดงผลบนมือถือ 375px (Shell ทุกหน้าจอ) | E23: Responsive | F23: เข้าสู่ระบบแล้ว; เปิด DevTools โหมดอุปกรณ์ iPhone SE/375×667 | G23: 1. เปิดหน้าจอที่ความกว้าง 375px 2. เปิด/ปิดเมนูด้านซ้ายด้วยปุ่มแฮมเบอร์เกอร์ 3. เลื่อนตาราง/การ์ดในแนวนอน-แนวตั้ง 4. เปิดฟอร์ม/Drawer หลักของหน้า (ถ้ามี) | H23: ความกว้าง 375px | I23: Sidebar ซ่อนเป็น off-canvas; KPI การ์ดเรียงลงแนวตั้ง; ตารางเลื่อนแนวนอนได้โดยไม่ล้นจอ; ปุ่ม/ข้อความไม่ถูกตัด; Modal/Drawer เต็มจอและปิดได้ | J23: Medium | K23: ผู้ดูแลระบบสูงสุด (admin) | M23: ยังไม่ทดสอบ | Q23: ทุกหน้าจอ (c916d36c เป็นหลัก)
A24: UAT-GEN-023 | B24: ส่วนกลาง (Shell / Navigation / ทั่วไป) | C24: Shell ทุกหน้าจอ | D24: แสดงผลบน Desktop 1920px และความอ่านง่ายธีมมืด (Shell ทุกหน้าจอ) | E24: UI | F24: เข้าสู่ระบบแล้ว; หน้าจอ 1920×1080 | G24: 1. เปิดหน้าจอที่ความกว้าง 1920px 2. ตรวจ layout กริด, การ์ด, กราฟ, ตาราง 3. ตรวจความคมชัดตัวอักษรบนพื้นหลัง navy (#0A1024) และ chip สถานะ | H24: ความกว้าง 1920px | I24: Layout ใช้พื้นที่เต็มไม่มีช่องว่างผิดปกติ; ตัวอักษรไทย (Noto Sans Thai) อ่านง่าย contrast ≥ 4.5:1; ป้ายกราฟ/legend ไม่ถูกตัด; สี chip ตรงความหมาย (แดง=เกินกำหนด, เหลือง=เตือน, เขียว=เสร็จ, ฟ้า=กำลังทำ, ม่วง=มอบหมาย) | J24: Low | K24: ผู้ดูแลระบบสูงสุด (admin) | M24: ยังไม่ทดสอบ | Q24: ทุกหน้าจอ (c916d36c เป็นหลัก)
A25: UAT-DSH-001 | B25: Command Center (แดชบอร์ด) | C25: Command Center | D25: แสดง KPI การ์ดหลักพร้อม count-up | E25: UI | F25: เข้าสู่ระบบแล้ว | G25: 1. เปิดหน้า Command Center 2. สังเกตการนับตัวเลข KPI | H25: - | I25: แสดง KPI: ทรัพย์สินทั้งหมด 32 (หยุด/ซ่อม 3), ราคาทุนรวม 24.84 ลบ., NBV 12.99 ลบ., WO ค้าง 18 (เกิน SLA 9), PM Compliance 30% (เป้า ≥90%), MTTR 3.0 ชม., ไลเซนส์ใกล้หมด, อะไหล่ต่ำกว่า ROP; ตัวเลข count-up แล้วหยุดที่ค่าถูกต้อง | J25: Medium | K25: ผู้บริหาร (exec) | M25: ยังไม่ทดสอบ | Q25: c916d36c
A26: UAT-DSH-002 | B26: Command Center (แดชบอร์ด) | C26: Command Center | D26: แถบ "ต้องดำเนินการ" นำทางไปยังรายการ | E26: Functional | F26: เข้าสู่ระบบแล้ว | G26: 1. คลิกการ์ด "WO เกิน SLA" 2. กลับมาแล้วคลิก "อะไหล่ต่ำกว่าจุดสั่งซื้อ" 3. คลิก "ไลเซนส์หมดใน 30 วัน" | H26: - | I26: แต่ละการ์ดนำไปยังหน้ารายการที่กรองไว้ตรงเงื่อนไข (WO เกิน SLA, อะไหล่ต่ำกว่า ROP, ไลเซนส์ใกล้หมด) | J26: High | K26: ผู้จัดการซ่อมบำรุง (maint.mgr) | M26: ยังไม่ทดสอบ | Q26: c916d36c
A27: UAT-DSH-003 | B27: Command Center (แดชบอร์ด) | C27: Command Center | D27: กราฟโดนัทสถานะใบสั่งงาน — legend ไม่ถูกตัด | E27: UI | F27: เข้าสู่ระบบแล้ว | G27: 1. ตรวจกราฟ "สถานะใบสั่งงานที่เปิดอยู่" 2. ตรวจ legend ทุกรายการที่ 1366px, 1920px และ 375px | H27: - | I27: Legend แสดงครบ (อนุมัติแล้ว, มอบหมายแล้ว, กำลังซ่อม, รออะไหล่/ผู้ขาย, ซ่อมเสร็จ) พร้อมจำนวน/% ข้อความไม่ถูกตัด ไม่ล้นการ์ด | J27: High | K27: ผู้ดูแลระบบสูงสุด (admin) | M27: ยังไม่ทดสอบ | Q27: c916d36c
A28: UAT-DSH-004 | B28: Command Center (แดชบอร์ด) | C28: Command Center | D28: ตาราง "งานเฝ้าระวัง SLA" | E28: Functional | F28: มี WO เกิน SLA | G28: 1. ตรวจคอลัมน์ เลขที่ WO / ทรัพย์สิน/อาการ / ระดับ / ช่าง / SLA 2. คลิก "ดูงานทั้งหมด" | H28: - | I28: SLA แสดงเวลาคงเหลือ/เกิน (สีแดงเมื่อเกิน) อัปเดตตามเวลา; ระดับ P1–P3 มี chip สี; ลิงก์ไปหน้าใบสั่งงาน | J28: High | K28: ผู้จัดการซ่อมบำรุง (maint.mgr) | M28: ยังไม่ทดสอบ | Q28: c916d36c
A29: UAT-DSH-005 | B29: Command Center (แดชบอร์ด) | C29: Command Center | D29: การ์ด "ใกล้หมดอายุ (60 วัน)" | E29: Functional | F29: เข้าสู่ระบบแล้ว | G29: 1. ตรวจรายการไลเซนส์/ประกัน/สอบเทียบ 2. คลิกรายการ | H29: - | I29: แสดงรายการเรียงตามวันคงเหลือน้อยไปมาก (เช่น M365 E3, FortiCare FW-001, Calibration GAU-011) พร้อมจำนวนวัน; คลิกแล้วไปหน้าที่เกี่ยวข้อง | J29: Medium | K29: ผู้ดูแลระบบ IT (it.admin) | M29: ยังไม่ทดสอบ | Q29: c916d36c
A30: UAT-DSH-006 | B30: Command Center (แดชบอร์ด) | C30: Command Center | D30: การ์ด "งบประมาณ ปีงบ 2569" | E30: UI | F30: เข้าสู่ระบบแล้ว | G30: 1. ตรวจ progress OPEX/CAPEX | H30: - | I30: แสดง OPEX ใช้แล้ว % และ CAPEX ใช้+ผูกพัน % พร้อมยอดคงเหลือ ตรงกับหน้า ต้นทุน & งบประมาณ | J30: Medium | K30: บัญชีสินทรัพย์ (account) | M30: ยังไม่ทดสอบ | Q30: c916d36c
A31: UAT-DSH-007 | B31: Command Center (แดชบอร์ด) | C31: Command Center | D31: กราฟ Bad actors (90 วัน) | E31: UI | F31: เข้าสู่ระบบแล้ว | G31: 1. hover แท่งกราฟ Bad actors | H31: - | I31: แสดง Top 5 เครื่องที่หยุดบ่อย (CONV-03, MTR-007, …) tooltip แสดง "xx ชม. · n ครั้ง" | J31: Low | K31: ผู้ดูแลระบบสูงสุด (admin) | M31: ยังไม่ทดสอบ | Q31: c916d36c
A32: UAT-DSH-008 | B32: Command Center (แดชบอร์ด) | C32: Command Center | D32: แผนที่ตำแหน่งทรัพย์สิน GPS/Geofence | E32: UI | F32: เข้าสู่ระบบแล้ว | G32: 1. ตรวจการ์ดแผนที่ | H32: - | I32: แสดงจุดทรัพย์สินและ Geofence; จุดนอกเขตเป็นสีแดง; จำนวนตรงกับหน้า ติดตามตำแหน่ง | J32: Low | K32: ผู้ดูแลระบบสูงสุด (admin) | M32: ยังไม่ทดสอบ | Q32: c916d36c
... A45: UAT-TV-004 | B45: จอแสดงผล TV | C45: จอแสดงผล TV | D45: ปุ่ม "ลิงก์จอติดผนัง" | E45: Functional | F45: เข้าสู่ระบบแล้ว | G45: 1. คลิก "ลิงก์จอติดผนัง" 2. วางลิงก์ในเบราว์เซอร์อื่นที่ไม่ได้ล็อกอิน | H45: - | I45: ระบบคัดลอกลิงก์ kiosk แล้วแจ้ง toast; ลิงก์เปิดจอ TV ได้โดยไม่ต้องล็อกอินแต่ดูได้อย่างเดียว; Audit Log บันทึก kiosk_create | J45: Medium | K45: ผู้ดูแลระบบ IT (it.admin) | M45: ยังไม่ทดสอบ | Q45: 2f8beddb
A46: UAT-TV-005 | B46: จอแสดงผล TV | C46: จอแสดงผล TV | D46: เพิกถอนลิงก์ kiosk | E46: Negative | F46: มีลิงก์ kiosk ที่สร้างไว้ | G46: 1. เพิกถอนลิงก์ (kiosk_revoke) 2. เปิดลิงก์เดิม | H46: - | I46: ลิงก์เดิมใช้ไม่ได้ แสดงข้อความหมดสิทธิ์ | J46: Medium | K46: ผู้ดูแลระบบ IT (it.admin) | M46: ยังไม่ทดสอบ | P46: ฟังก์ชันเพิกถอนอ้างอิงระบบเดิม (Audit: kiosk_revoke) — ยังไม่มีปุ่มใน mockup | Q46: 2f8beddb
A47: UAT-TV-006 | B47: จอแสดงผล TV | C47: จอแสดงผล TV | D47: ปุ่ม "เต็มจอ" | E47: Functional | F47: เข้าสู่ระบบแล้ว | G47: 1. คลิก "เต็มจอ" 2. กด Esc | H47: - | I47: เข้าโหมดเต็มจอ; ถ้าเบราว์เซอร์ไม่อนุญาตแสดงข้อความ "เบราว์เซอร์ไม่อนุญาตโหมดเต็มจอ" | J47: Low | K47: ผู้ดูแลระบบสูงสุด (admin) | M47: ยังไม่ทดสอบ | Q47: 2f8beddb
A48: UAT-TV-007 | B48: จอแสดงผล TV | C48: จอแสดงผล TV | D48: การ์ดเครื่องหยุด/ซ่อม และ PM ที่จะถึง | E48: UI | F48: เข้าสู่ระบบแล้ว | G48: 1. ตรวจส่วน "เครื่องหยุด/ซ่อม" และ "PM ที่จะถึง" | H48: - | I48: แสดงเครื่องหยุด (CONV-03, MTR-007, AHU-05) พร้อมสถานะ ที่ตั้ง เวลาเริ่ม downtime; รายการ PM พร้อมวันที่ พ.ศ. | J48: Low | K48: ผู้ดูแลระบบสูงสุด (admin) | M48: ยังไม่ทดสอบ | Q48: 2f8beddb
A49: UAT-TV-008 | B49: จอแสดงผล TV | C49: จอแสดงผล TV | D49: สัญญาณเตือน IoT/Geofence | E49: UI | F49: มีเซนเซอร์เกินเกณฑ์ | G49: 1. ตรวจส่วน "สัญญาณเตือน" | H49: - | I49: แสดง TMP-MTR007 86.5°C และทรัพย์สินนอก Geofence 2 รายการ ตรงกับหน้า IoT/Tracking | J49: Medium | K49: ผู้ดูแลระบบสูงสุด (admin) | M49: ยังไม่ทดสอบ | Q49: 2f8beddb
A50: UAT-TV-009 | B50: จอแสดงผล TV | C50: จอแสดงผล TV | D50: เลือกไซต์บนจอ TV | E50: Functional | F50: เข้าสู่ระบบแล้ว | G50: 1. เปลี่ยนไซต์ใน dropdown | H50: - | I50: ข้อมูลทั้งจอเปลี่ยนตามไซต์ | J50: Medium | K50: ผู้ดูแลระบบสูงสุด (admin) | M50: ยังไม่ทดสอบ | Q50: 2f8beddb
A51: UAT-TV-010 | B51: จอแสดงผล TV | C51: จอแสดงผล TV | D51: แสดงผลบนจอ TV 1920×1080 และ 4K | E51: Responsive | F51: จอ 1920×1080 / 3840×2160 | G51: 1. เปิดจอ TV เต็มจอ 2. ตรวจการจัดวางทุกส่วน | H51: - | I51: ทุกส่วนอยู่ในจอเดียวไม่ต้องเลื่อน; ตัวอักษรไม่แตก/ไม่ถูกตัด | J51: Medium | K51: ผู้ดูแลระบบสูงสุด (admin) | M51: ยังไม่ทดสอบ | Q51: 2f8beddb
A52: UAT-TV-011 | B52: จอแสดงผล TV | C52: จอแสดงผล TV | D52: Ticker/การเลื่อนรายการอัตโนมัติ | E52: UI | F52: มีใบงานมากกว่าที่แสดงได้ | G52: 1. ปล่อยหน้าจอทิ้งไว้ | H52: - | I52: รายการเลื่อนวนอัตโนมัติอย่างนุ่มนวล ไม่กระตุก | J52: Low | K52: ผู้ดูแลระบบสูงสุด (admin) | M52: ยังไม่ทดสอบ | Q52: 2f8beddb
...

Sheet End-to-End Scenarios
A1: Scenario ID | B1: ชื่อ Scenario | C1: วัตถุประสงค์ | D1: เงื่อนไขก่อนทดสอบ | E1: ขั้นที่ | F1: โมดูล/หน้าจอ | G1: บทบาท | H1: การดำเนินการ | I1: ผลลัพธ์ที่คาดหวัง | J1: TC อ้างอิง | K1: ผลทดสอบจริง | L1: สถานะ | M1: ผู้ทดสอบ | N1: วันที่ทดสอบ | O1: หมายเหตุ/Defect ID
A2: E2E-01 | B2: แจ้งซ่อม → ใบสั่งงาน → เบิกอะไหล่ → ปิดงาน → ต้นทุน/งบประมาณ | C2: ยืนยันว่าข้อมูลการซ่อมไหลจากการแจ้งซ่อมจนถึงต้นทุนและ KPI ครบถ้วน | D2: ทรัพย์สิน CONV-03 สถานะใช้งาน; ลูกปืน 6205-2RS คงเหลือ WH-SKN ≥ 3; งบ OPEX ศูนย์ต้นทุน MT-01 มีอยู่ | E2: 1 | F2: ใบแจ้งซ่อม | G2: ผู้แจ้งซ่อม/ผู้ใช้งานทั่วไป (user) | H2: แจ้งซ่อม CONV-03 ผ่าน wizard ความเร่งด่วน เครื่องหยุด แนบรูป | I2: ได้เลขใบแจ้ง สถานะ รอคัดกรอง; ผู้จัดการได้รับแจ้งเตือน | J2: UAT-RR-002 | L2: ยังไม่ทดสอบ
A3: E2E-01 | B3: แจ้งซ่อม → ใบสั่งงาน → เบิกอะไหล่ → ปิดงาน → ต้นทุน/งบประมาณ | C3: ยืนยันว่าข้อมูลการซ่อมไหลจากการแจ้งซ่อมจนถึงต้นทุนและ KPI ครบถ้วน | D3: ทรัพย์สิน CONV-03 สถานะใช้งาน; ลูกปืน 6205-2RS คงเหลือ WH-SKN ≥ 3; งบ OPEX ศูนย์ต้นทุน MT-01 มีอยู่ | E3: 2 | F3: ใบแจ้งซ่อม | G3: ผู้จัดการซ่อมบำรุง (maint.mgr) | H3: คัดกรองและกด เปิดใบสั่งงาน เลือก Breakdown/P1/ช่าง thanapol | I3: สร้าง WO สถานะ มอบหมายแล้ว; ใบแจ้งเป็น เปิดใบสั่งงานแล้ว | J3: UAT-RR-008 | L3: ยังไม่ทดสอบ
A4: E2E-01 | B4: แจ้งซ่อม → ใบสั่งงาน → เบิกอะไหล่ → ปิดงาน → ต้นทุน/งบประมาณ | C4: ยืนยันว่าข้อมูลการซ่อมไหลจากการแจ้งซ่อมจนถึงต้นทุนและ KPI ครบถ้วน | D4: ทรัพย์สิน CONV-03 สถานะใช้งาน; ลูกปืน 6205-2RS คงเหลือ WH-SKN ≥ 3; งบ OPEX ศูนย์ต้นทุน MT-01 มีอยู่ | E4: 3 | F4: ใบสั่งงาน | G4: ช่างซ่อมบำรุง (somchai) | H4: ช่างเปิด WO กด เริ่มงาน | I4: สถานะ กำลังซ่อม; ไทม์ไลน์บันทึกเวลาเริ่ม | J4: UAT-WO-012 | L4: ยังไม่ทดสอบ
A5: E2E-01 | B5: แจ้งซ่อม → ใบสั่งงาน → เบิกอะไหล่ → ปิดงาน → ต้นทุน/งบประมาณ | C5: ยืนยันว่าข้อมูลการซ่อมไหลจากการแจ้งซ่อมจนถึงต้นทุนและ KPI ครบถ้วน | D5: ทรัพย์สิน CONV-03 สถานะใช้งาน; ลูกปืน 6205-2RS คงเหลือ WH-SKN ≥ 3; งบ OPEX ศูนย์ต้นทุน MT-01 มีอยู่ | E5: 4 | F5: ใบสั่งงาน | G5: ช่างซ่อมบำรุง (somchai) | H5: เปลี่ยนสถานะ รออะไหล่/ผู้ขาย | I5: SLA หยุดนับ | J5: UAT-WO-013 | L5: ยังไม่ทดสอบ
A6: E2E-01 | B6: แจ้งซ่อม → ใบสั่งงาน → เบิกอะไหล่ → ปิดงาน → ต้นทุน/งบประมาณ | C6: ยืนยันว่าข้อมูลการซ่อมไหลจากการแจ้งซ่อมจนถึงต้นทุนและ KPI ครบถ้วน | D6: ทรัพย์สิน CONV-03 สถานะใช้งาน; ลูกปืน 6205-2RS คงเหลือ WH-SKN ≥ 3; งบ OPEX ศูนย์ต้นทุน MT-01 มีอยู่ | E6: 5 | F6: คลังอะไหล่ | G6: เจ้าหน้าที่คลัง (store) | H6: เบิกลูกปืน 6205-2RS 2 ตัว อ้างอิง WO | I6: คงเหลือลด 2; ความเคลื่อนไหว เบิก WO | J6: UAT-SP-009 | L6: ยังไม่ทดสอบ
A7: E2E-01 | B7: แจ้งซ่อม → ใบสั่งงาน → เบิกอะไหล่ → ปิดงาน → ต้นทุน/งบประมาณ | C7: ยืนยันว่าข้อมูลการซ่อมไหลจากการแจ้งซ่อมจนถึงต้นทุนและ KPI ครบถ้วน | D7: ทรัพย์สิน CONV-03 สถานะใช้งาน; ลูกปืน 6205-2RS คงเหลือ WH-SKN ≥ 3; งบ OPEX ศูนย์ต้นทุน MT-01 มีอยู่ | E7: 6 | F7: ใบสั่งงาน | G7: ช่างซ่อมบำรุง (somchai) | H7: ทำงานต่อ กรอกเช็คลิสต์ ค่าแรง 3 ชม. แนบรูปหลังซ่อม กด ปิดงาน | I7: สถานะ ปิดงาน/รอตรวจรับ; Downtime หยุดนับ; ต้นทุน = ค่าแรง + อะไหล่ | J7: UAT-WO-012 | L7: ยังไม่ทดสอบ
A8: E2E-01 | B8: แจ้งซ่อม → ใบสั่งงาน → เบิกอะไหล่ → ปิดงาน → ต้นทุน/งบประมาณ | C8: ยืนยันว่าข้อมูลการซ่อมไหลจากการแจ้งซ่อมจนถึงต้นทุนและ KPI ครบถ้วน | D8: ทรัพย์สิน CONV-03 สถานะใช้งาน; ลูกปืน 6205-2RS คงเหลือ WH-SKN ≥ 3; งบ OPEX ศูนย์ต้นทุน MT-01 มีอยู่ | E8: 7 | F8: ต้นทุน & งบประมาณ | G8: บัญชีสินทรัพย์ (account) | H8: เปิดบรรทัดงบ OPEX ศูนย์ต้นทุน MT-01 | I8: ยอดจริงเพิ่มเท่าต้นทุน WO | J8: UAT-BUD-008 | L8: ยังไม่ทดสอบ
A9: E2E-01 | B9: แจ้งซ่อม → ใบสั่งงาน → เบิกอะไหล่ → ปิดงาน → ต้นทุน/งบประมาณ | C9: ยืนยันว่าข้อมูลการซ่อมไหลจากการแจ้งซ่อมจนถึงต้นทุนและ KPI ครบถ้วน | D9: ทรัพย์สิน CONV-03 สถานะใช้งาน; ลูกปืน 6205-2RS คงเหลือ WH-SKN ≥ 3; งบ OPEX ศูนย์ต้นทุน MT-01 มีอยู่ | E9: 8 | F9: Command Center / รายงาน | G9: ผู้บริหาร (exec) | H9: ตรวจ MTTR, WO ค้าง, Bad actors และรายงาน KPI รายเดือน | I9: ตัวเลขอัปเดตสอดคล้องกัน | J9: UAT-RPT-007 | L9: ยังไม่ทดสอบ
A10: E2E-01 | B10: แจ้งซ่อม → ใบสั่งงาน → เบิกอะไหล่ → ปิดงาน → ต้นทุน/งบประมาณ | C10: ยืนยันว่าข้อมูลการซ่อมไหลจากการแจ้งซ่อมจนถึงต้นทุนและ KPI ครบถ้วน | D10: ทรัพย์สิน CONV-03 สถานะใช้งาน; ลูกปืน 6205-2RS คงเหลือ WH-SKN ≥ 3; งบ OPEX ศูนย์ต้นทุน MT-01 มีอยู่ | E10: 9 | F10: Audit Log | G10: ผู้ตรวจสอบ (auditor) | H10: กรองโมดูล wo/requests | I10: มีเหตุการณ์ครบทุกขั้น | J10: UAT-AUD-008 | L10: ยังไม่ทดสอบ
A11: E2E-02 | B11: PR → PO → รับของ → ขึ้นทะเบียนทรัพย์สิน → ค่าเสื่อมราคา | C11: ยืนยันวงจรจัดซื้อสินทรัพย์ถาวรจนถึงบัญชีค่าเสื่อม | D11: งบ CAPEX คงเหลือพอ; ผู้ขาย บจก. ไซเบอร์ซีเคียว อยู่ในข้อมูลหลัก; วงเงิน PO 50,000 | E11: 1 | F11: จัดซื้อ PR/PO | G11: เจ้าหน้าที่จัดซื้อ (purchase) | H11: สร้าง PR ประเภท ขอซื้อทั่วไป งบ CAPEX: Notebook 5 × 32,000 | I11: ยอดรวม 160,000.00; สถานะ รออนุมัติ | J11: UAT-PUR-002 | L11: ยังไม่ทดสอบ
A12: E2E-02 | B12: PR → PO → รับของ → ขึ้นทะเบียนทรัพย์สิน → ค่าเสื่อมราคา | C12: ยืนยันวงจรจัดซื้อสินทรัพย์ถาวรจนถึงบัญชีค่าเสื่อม | D12: งบ CAPEX คงเหลือพอ; ผู้ขาย บจก. ไซเบอร์ซีเคียว อยู่ในข้อมูลหลัก; วงเงิน PO 50,000 | E12: 2 | F12: จัดซื้อ PR/PO | G12: ผู้บริหาร (exec) | H12: อนุมัติ PR (ผู้ขอไม่ใช่ผู้อนุมัติ) | I12: สถานะ อนุมัติแล้ว | J12: UAT-PUR-007 | L12: ยังไม่ทดสอบ
A13: E2E-02 | B13: PR → PO → รับของ → ขึ้นทะเบียนทรัพย์สิน → ค่าเสื่อมราคา | C13: ยืนยันวงจรจัดซื้อสินทรัพย์ถาวรจนถึงบัญชีค่าเสื่อม | D13: งบ CAPEX คงเหลือพอ; ผู้ขาย บจก. ไซเบอร์ซีเคียว อยู่ในข้อมูลหลัก; วงเงิน PO 50,000 | E13: 3 | F13: จัดซื้อ PR/PO | G13: เจ้าหน้าที่จัดซื้อ (purchase) | H13: ออก PO (เกินวงเงินต้องผ่านอนุมัติ) | I13: PO สถานะ รอส่ง; PR ออก PO แล้ว; CAPEX ผูกพัน +171,200 (รวม VAT) | J13: UAT-PUR-011 | L13: ยังไม่ทดสอบ
... A77: E2E-12 | B77: Custom Field Builder → ใช้ในฟอร์ม → ค้นหา/รายงาน/ส่งออก | C77: ยืนยันว่าฟิลด์ที่ผู้ใช้กำหนดเองใช้ได้ครบวงจร | D77: ผู้ดูแลระบบมีสิทธิ์ข้อมูลหลัก | E77: 5 | F77: ทะเบียนทรัพย์สินกลาง | G77: ผู้จัดการทรัพย์สิน (asset.mgr) | H77: ส่งออก Excel | I77: คอลัมน์ IP Address อยู่ในไฟล์ | J77: UAT-AST-020 | L77: ยังไม่ทดสอบ

Sheet Defect Log
A1: Defect ID | B1: TC ID | C1: โมดูล | D1: หน้าจอ | E1: หัวข้อ Defect | F1: รายละเอียด | G1: ขั้นตอนการทำซ้ำ | H1: ผลที่คาดหวัง | I1: ผลที่เกิดขึ้นจริง | J1: ความรุนแรง (Severity) | K1: ความสำคัญในการแก้ (Priority) | L1: สถานะ Defect | M1: ผู้แจ้ง | N1: วันที่พบ | O1: ผู้รับผิดชอบแก้ไข | P1: วันที่กำหนดแก้ | Q1: วันที่แก้ไขเสร็จ | R1: ผลทดสอบซ้ำ (Retest) | S1: วันที่ทดสอบซ้ำ | T1: หมายเหตุ/ไฟล์แนบ
A2: DEF-001 | C2: =IF(B2="","",IFERROR(INDEX('Test Cases'!$B$2:$B$546,MATCH(B2,'Test Cases'!$A$2:$A$546,0)),"")) | D2: =IF(B2="","",IFERROR(INDEX('Test Cases'!$C$2:$C$546,MATCH(B2,'Test Cases'!$A$2:$A$546,0)),""))
A3: DEF-002 | C3: =IF(B3="","",IFERROR(INDEX('Test Cases'!$B$2:$B$546,MATCH(B3,'Test Cases'!$A$2:$A$546,0)),"")) | D3: =IF(B3="","",IFERROR(INDEX('Test Cases'!$C$2:$C$546,MATCH(B3,'Test Cases'!$A$2:$A$546,0)),""))
A4: DEF-003 | C4: =IF(B4="","",IFERROR(INDEX('Test Cases'!$B$2:$B$546,MATCH(B4,'Test Cases'!$A$2:$A$546,0)),"")) | D4: =IF(B4="","",IFERROR(INDEX('Test Cases'!$C$2:$C$546,MATCH(B4,'Test Cases'!$A$2:$A$546,0)),""))
A5: DEF-004 | C5: =IF(B5="","",IFERROR(INDEX('Test Cases'!$B$2:$B$546,MATCH(B5,'Test Cases'!$A$2:$A$546,0)),"")) | D5: =IF(B5="","",IFERROR(INDEX('Test Cases'!$C$2:$C$546,MATCH(B5,'Test Cases'!$A$2:$A$546,0)),""))
A6: DEF-005 | C6: =IF(B6="","",IFERROR(INDEX('Test Cases'!$B$2:$B$546,MATCH(B6,'Test Cases'!$A$2:$A$546,0)),"")) | D6: =IF(B6="","",IFERROR(INDEX('Test Cases'!$C$2:$C$546,MATCH(B6,'Test Cases'!$A$2:$A$546,0)),""))
A7: DEF-006 | C7: =IF(B7="","",IFERROR(INDEX('Test Cases'!$B$2:$B$546,MATCH(B7,'Test Cases'!$A$2:$A$546,0)),"")) | D7: =IF(B7="","",IFERROR(INDEX('Test Cases'!$C$2:$C$546,MATCH(B7,'Test Cases'!$A$2:$A$546,0)),""))
A8: DEF-007 | C8: =IF(B8="","",IFERROR(INDEX('Test Cases'!$B$2:$B$546,MATCH(B8,'Test Cases'!$A$2:$A$546,0)),"")) | D8: =IF(B8="","",IFERROR(INDEX('Test Cases'!$C$2:$C$546,MATCH(B8,'Test Cases'!$A$2:$A$546,0)),""))
A9: DEF-008 | C9: =IF(B9="","",IFERROR(INDEX('Test Cases'!$B$2:$B$546,MATCH(B9,'Test Cases'!$A$2:$A$546,0)),"")) | D9: =IF(B9="","",IFERROR(INDEX('Test Cases'!$C$2:$C$546,MATCH(B9,'Test Cases'!$A$2:$A$546,0)),""))
A10: DEF-009 | C10: =IF(B10="","",IFERROR(INDEX('Test Cases'!$B$2:$B$546,MATCH(B10,'Test Cases'!$A$2:$A$546,0)),"")) | D10: =IF(B10="","",IFERROR(INDEX('Test Cases'!$C$2:$C$546,MATCH(B10,'Test Cases'!$A$2:$A$546,0)),""))
A11: DEF-010 | C11: =IF(B11="","",IFERROR(INDEX('Test Cases'!$B$2:$B$546,MATCH(B11,'Test Cases'!$A$2:$A$546,0)),"")) | D11: =IF(B11="","",IFERROR(INDEX('Test Cases'!$C$2:$C$546,MATCH(B11,'Test Cases'!$A$2:$A$546,0)),""))
A12: DEF-011 | C12: =IF(B12="","",IFERROR(INDEX('Test Cases'!$B$2:$B$546,MATCH(B12,'Test Cases'!$A$2:$A$546,0)),"")) | D12: =IF(B12="","",IFERROR(INDEX('Test Cases'!$C$2:$C$546,MATCH(B12,'Test Cases'!$A$2:$A$546,0)),""))
A13: DEF-012 | C13: =IF(B13="","",IFERROR(INDEX('Test Cases'!$B$2:$B$546,MATCH(B13,'Test Cases'!$A$2:$A$546,0)),"")) | D13: =IF(B13="","",IFERROR(INDEX('Test Cases'!$C$2:$C$546,MATCH(B13,'Test Cases'!$A$2:$A$546,0)),""))
... A201: DEF-200 | C201: =IF(B201="","",IFERROR(INDEX('Test Cases'!$B$2:$B$546,MATCH(B201,'Test Cases'!$A$2:$A$546,0)),"")) | D201: =IF(B201="","",IFERROR(INDEX('Test Cases'!$C$2:$C$546,MATCH(B201,'Test Cases'!$A$2:$A$546,0)),""))

Sheet Sign-off
B2: การรับรองผลการทดสอบ UAT (User Acceptance Sign-off)
B3: โครงการ TOTAL IT SERVICES (IT&MAINT — Smart Asset · Smart Work) · เอกสาร UAT เวอร์ชัน 1.0 · วันที่ 17/10/2569
B5: สรุปผลการทดสอบ (คำนวณอัตโนมัติจากชีต Test Cases)
B6: จำนวน Test Case ทั้งหมด | C6: =COUNTA('Test Cases'!A2:A546)
B7: ผ่าน | C7: =COUNTIF('Test Cases'!M2:M546,"ผ่าน")
B8: ไม่ผ่าน | C8: =COUNTIF('Test Cases'!M2:M546,"ไม่ผ่าน")
B9: ติดเงื่อนไข | C9: =COUNTIF('Test Cases'!M2:M546,"ติดเงื่อนไข")
B10: ยังไม่ทดสอบ | C10: =COUNTIF('Test Cases'!M2:M546,"ยังไม่ทดสอบ")
B11: % ผ่าน (จากที่ทดสอบแล้ว) | C11: =IFERROR(C7/(C7+C8+C9),0)
B12: Defect Critical/High ที่ยังไม่ปิด | C12: =COUNTIFS('Defect Log'!J:J,"Critical",'Defect Log'!L:L,"<>ปิด (Closed)",'Defect Log'!L:L,"<>ปฏิเสธ (Rejected)")+COUNTIFS('Defect Log'!J:J,"High",'Defect Log'!L:L,"<>ปิด (Closed)",'Defect Log'!L:L,"<>ปฏิเสธ (Rejected)")
B13: E2E Scenario ผ่าน (ขั้นตอน) | C13: =COUNTIF('End-to-End Scenarios'!L2:L77,"ผ่าน")&" / "&COUNTA('End-to-End Scenarios'!E2:E77)
B15: คำรับรอง
B16: ข้าพเจ้าได้ทดสอบ/ตรวจสอบผลการทดสอบระบบ TOTAL IT SERVICES ตามเอกสารฉบับนี้แล้ว และพิจารณาว่าระบบเป็นไปตามเกณฑ์การยอมรับ (Exit Criteria) ที่ระบุในหน้าปก ยกเว้นรายการที่ระบุไว้ในช่องความเห็น ซึ่งต้องแก้ไขตามกำหนดเวลาที่ตกลงร่วมกัน
B19: ฝ่าย / บทบาท | C19: ชื่อ-นามสกุล | D19: ตำแหน่ง | E19: ผลการพิจารณา | F19: ความเห็น / เงื่อนไข | G19: ลายมือชื่อ | H19: วันที่
B20: ผู้ใช้งานหลัก (Key User)
B21: ฝ่ายเทคโนโลยีสารสนเทศ (IT)
B22: ฝ่ายซ่อมบำรุง
B23: ฝ่ายบัญชี/การเงิน
B24: ผู้อนุมัติ (Project Sponsor / ผู้บริหาร)
